<?xml version="1.0" ?>
<!-- =================================================================================== -->
<!-- |    This document was autogenerated by xacro from src/neo_mpo_500-2/robot_model/mpo_500.urdf.xacro | -->
<!-- |    EDITING THIS FILE BY HAND IS NOT RECOMMENDED                                 | -->
<!-- =================================================================================== -->
<robot name="mpo_500">
  <link name="base_link"/>
  <joint name="base_footprint_joint" type="fixed">
    <origin rpy="0 0 0" xyz="0 0 0"/>
    <axis xyz="0 0 -1"/>
    <joint_properties damping="1" friction="1"/>
    <parent link="base_link"/>
    <child link="base_footprint"/>
  </joint>
  <!-- Link -->
  <link name="base_footprint">
    <inertial>
      <mass value="80"/>
      <origin xyz="0 0 0"/>
      <inertia ixx="3.253" ixy="0.0" ixz="0.0" iyy="3.253" iyz="0.0" izz="3.253"/>
    </inertial>
    <visual>
      <origin rpy="-1.571 0 1.571" xyz="0. 0. 0"/>
      <geometry>
        <mesh filename="package://neo_mpo_500-2/robot_model/meshes/MPO_500/MPO-500-BODY.dae" scale="0.001 0.001 0.001"/>
      </geometry>
    </visual>
    <collision>
      <origin rpy="-1.571 0 1.571" xyz="0. 0. 0.0"/>
      <geometry>
        <!--<box size="0.68 0.41 0.25"/> -->
        <mesh filename="package://neo_mpo_500-2/robot_model/meshes/MPO_500/MPO-500-BODY.dae" scale="0.001 0.001 0.001"/>
      </geometry>
    </collision>
  </link>
  <joint name="mpo_500_wheel_front_left_joint" type="fixed">
    <origin rpy="0 0 0" xyz="0.25 0.28 0.13"/>
    <axis xyz="0 1 0"/>
    <joint_properties damping="100" friction="1000"/>
    <limit effort="1000.0" lower="-1e+16" upper="1e+16" velocity="3.5"/>
    <joint_properties damping="1.0" friction="1"/>
    <parent link="base_footprint"/>
    <child link="mpo_500_wheel_front_left_link"/>
  </joint>
  <link name="mpo_500_wheel_front_left_link" type="wheel">
    <inertial>
      <mass value="1"/>
      <origin rpy="0 0 0" xyz="0 0 0"/>
      <inertia ixx="0.00044332" ixy="0" ixz="0" iyy="0.00044332" iyz="0" izz="0.00072"/>
    </inertial>
    <visual>
      <origin rpy="0 0 0" xyz="0 0 0"/>
      <geometry>
        <mesh filename="package://neo_mpo_500-2/robot_model/meshes/MPO_500/MPO-500-WHEEL.dae" scale="0.001 0.001 0.001"/>
      </geometry>
    </visual>
    <collision>
      <origin rpy="0 0 0" xyz="0 0 0"/>
      <geometry>
        <mesh filename="package://neo_mpo_500-2/robot_model/meshes/MPO_500/MPO-500-WHEEL.dae" scale="0.001 0.001 0.001"/>
      </geometry>
    </collision>
  </link>
  <joint name="mpo_500_wheel_front_right_joint" type="fixed">
    <origin rpy="0 0 3.14" xyz="0.25 -0.28 0.13"/>
    <axis xyz="0 1 0"/>
    <joint_properties damping="100" friction="1000"/>
    <limit effort="1000.0" lower="-1e+16" upper="1e+16" velocity="3.5"/>
    <joint_properties damping="1.0" friction="1"/>
    <parent link="base_footprint"/>
    <child link="mpo_500_wheel_front_right_link"/>
  </joint>
  <link name="mpo_500_wheel_front_right_link" type="wheel">
    <inertial>
      <mass value="1"/>
      <origin rpy="0 0 0" xyz="0 0 0"/>
      <inertia ixx="0.00044332" ixy="0" ixz="0" iyy="0.00044332" iyz="0" izz="0.00072"/>
    </inertial>
    <visual>
      <origin rpy="0 0 0" xyz="0 0 0"/>
      <geometry>
        <mesh filename="package://neo_mpo_500-2/robot_model/meshes/MPO_500/MPO-500-WHEEL.dae" scale="0.001 0.001 0.001"/>
      </geometry>
    </visual>
    <collision>
      <origin rpy="0 0 0" xyz="0 0 0"/>
      <geometry>
        <mesh filename="package://neo_mpo_500-2/robot_model/meshes/MPO_500/MPO-500-WHEEL.dae" scale="0.001 0.001 0.001"/>
      </geometry>
    </collision>
  </link>
  <joint name="mpo_500_wheel_back_left_joint" type="fixed">
    <origin rpy="0 0 0" xyz="-0.25 0.28 0.13"/>
    <axis xyz="0 1 0"/>
    <joint_properties damping="100" friction="1000"/>
    <limit effort="1000.0" lower="-1e+16" upper="1e+16" velocity="3.5"/>
    <joint_properties damping="1.0" friction="1"/>
    <parent link="base_footprint"/>
    <child link="mpo_500_wheel_back_left_link"/>
  </joint>
  <link name="mpo_500_wheel_back_left_link" type="wheel">
    <inertial>
      <mass value="1"/>
      <origin rpy="0 0 0" xyz="0 0 0"/>
      <inertia ixx="0.00044332" ixy="0" ixz="0" iyy="0.00044332" iyz="0" izz="0.00072"/>
    </inertial>
    <visual>
      <origin rpy="0 0 0" xyz="0 0 0"/>
      <geometry>
        <mesh filename="package://neo_mpo_500-2/robot_model/meshes/MPO_500/MPO-500-WHEEL.dae" scale="0.001 0.001 0.001"/>
      </geometry>
    </visual>
    <collision>
      <origin rpy="0 0 0" xyz="0 0 0"/>
      <geometry>
        <mesh filename="package://neo_mpo_500-2/robot_model/meshes/MPO_500/MPO-500-WHEEL.dae" scale="0.001 0.001 0.001"/>
      </geometry>
    </collision>
  </link>
  <joint name="mpo_500_wheel_back_right_joint" type="fixed">
    <origin rpy="0 0 3.14" xyz="-0.25 -0.28 0.13"/>
    <axis xyz="0 1 0"/>
    <joint_properties damping="100" friction="1000"/>
    <limit effort="1000.0" lower="-1e+16" upper="1e+16" velocity="3.5"/>
    <joint_properties damping="1.0" friction="1"/>
    <parent link="base_footprint"/>
    <child link="mpo_500_wheel_back_right_link"/>
  </joint>
  <link name="mpo_500_wheel_back_right_link" type="wheel">
    <inertial>
      <mass value="1"/>
      <origin rpy="0 0 0" xyz="0 0 0"/>
      <inertia ixx="0.00044332" ixy="0" ixz="0" iyy="0.00044332" iyz="0" izz="0.00072"/>
    </inertial>
    <visual>
      <origin rpy="0 0 0" xyz="0 0 0"/>
      <geometry>
        <mesh filename="package://neo_mpo_500-2/robot_model/meshes/MPO_500/MPO-500-WHEEL.dae" scale="0.001 0.001 0.001"/>
      </geometry>
    </visual>
    <collision>
      <origin rpy="0 0 0" xyz="0 0 0"/>
      <geometry>
        <mesh filename="package://neo_mpo_500-2/robot_model/meshes/MPO_500/MPO-500-WHEEL.dae" scale="0.001 0.001 0.001"/>
      </geometry>
    </collision>
  </link>
  <joint name="lidar_1_joint" type="fixed">
    <axis xyz="0 1 0"/>
    <origin rpy="0 0 0" xyz="0.442 0 0.372"/>
    <parent link="base_link"/>
    <child link="lidar_1_link"/>
  </joint>
  <link name="lidar_1_link" type="laser">
    <inertial>
      <mass value="0.001"/>
      <origin rpy="0 0 0" xyz="0 0 0"/>
      <inertia ixx="0.0001" ixy="0" ixz="0" iyy="0.000001" iyz="0" izz="0.0001"/>
    </inertial>
    <visual>
      <origin rpy="-1.57 0 3.14" xyz="0 0 -0.12"/>
      <geometry>
        <mesh filename="package://neo_mpo_500-2/robot_model/meshes/MPO_500/SICK-S300.dae" scale="0.001 0.001 0.001"/>
      </geometry>
    </visual>
    <collision>
      <origin rpy="-1.57 0 3.14" xyz="0 0 -0.12"/>
      <geometry>
        <mesh filename="package://neo_mpo_500-2/robot_model/meshes/MPO_500/SICK-S300.dae" scale="0.001 0.001 0.001"/>
      </geometry>
    </collision>
  </link>
  <joint name="lidar_2_joint" type="fixed">
    <axis xyz="0 1 0"/>
    <origin rpy="0 0 3.14" xyz="-0.442 0 0.372"/>
    <parent link="base_link"/>
    <child link="lidar_2_link"/>
  </joint>
  <link name="lidar_2_link" type="laser">
    <inertial>
      <mass value="0.001"/>
      <origin rpy="0 0 0" xyz="0 0 0"/>
      <inertia ixx="0.0001" ixy="0" ixz="0" iyy="0.000001" iyz="0" izz="0.0001"/>
    </inertial>
    <visual>
      <origin rpy="-1.57 0 3.14" xyz="0 0 -0.12"/>
      <geometry>
        <mesh filename="package://neo_mpo_500-2/robot_model/meshes/MPO_500/SICK-S300.dae" scale="0.001 0.001 0.001"/>
      </geometry>
    </visual>
    <collision>
      <origin rpy="-1.57 0 3.14" xyz="0 0 -0.12"/>
      <geometry>
        <mesh filename="package://neo_mpo_500-2/robot_model/meshes/MPO_500/SICK-S300.dae" scale="0.001 0.001 0.001"/>
      </geometry>
    </collision>
  </link>
  <!--+++++++++++++++++++ IMU ++++++++++++++++++++++++-->
  <!-- Comment or uncomment based on your requirement -->
  <!--   <xacro:imu name="imu_1" parent="base_link">
    <origin xyz="0.100 0 0.300" rpy="0 0 3.14" />
  </xacro:imu> -->
  <!--+++++++++++++++++++ Ultra Sonic ++++++++++++++++++++++++-->
  <!-- Comment or uncomment based on your requirement -->
  <!-- SENSOR 1 -->
  <!-- xacro:us_sensor name="us_1" parent="base_link">
    <origin xyz="0.100 0 0.300" rpy="0 3.14 3.14" />
  </xacro:us_sensor-->
  <!-- SENSOR 2 -->
  <!-- xacro:us_sensor name="us_2" parent="base_link">
    <origin xyz="0.110 0 0.300" rpy="0 3.14 3.14" />
  </xacro:us_sensor-->
  <!-- SENSOR 3 -->
  <!-- xacro:us_sensor name="us_3" parent="base_link">
    <origin xyz="0.120 0 0.300" rpy="0 3.14 3.14" />
  </xacro:us_sensor-->
  <!-- SENSOR 4 -->
  <!-- xacro:us_sensor name="us_4" parent="base_link">
    <origin xyz="0.130 0 0.300" rpy="0 3.14 3.14" />
  </xacro:us_sensor-->
  <!-- SENSOR 5 -->
  <!-- xacro:us_sensor name="us_5" parent="base_link">
    <origin xyz="0.140 0 0.300" rpy="0 3.14 3.14" />
  </xacro:us_sensor-->
  <!-- SENSOR 6 -->
  <!-- xacro:us_sensor name="us_6" parent="base_link">
    <origin xyz="0.150 0 0.300" rpy="0 3.14 3.14" />
  </xacro:us_sensor-->
  <!-- SENSOR 7 -->
  <!-- xacro:us_sensor name="us_7" parent="base_link">
    <origin xyz="0.160 0 0.300" rpy="0 3.14 3.14" />
  </xacro:us_sensor-->
  <!-- SENSOR 8 -->
  <!-- xacro:us_sensor name="us_8" parent="base_link">
    <origin xyz="0.170 0 0.300" rpy="0 3.14 3.14" />
  </xacro:us_sensor-->
  <!-- SENSOR 9 -->
  <!-- xacro:us_sensor name="us_9" parent="base_link">
    <origin xyz="0.180 0 0.300" rpy="0 3.14 3.14" />
  </xacro:us_sensor-->
  <!-- SENSOR 10 -->
  <!-- xacro:us_sensor name="us_10" parent="base_link">
    <origin xyz="0.100 0 0.300" rpy="0 3.14 3.14" />
  </xacro:us_sensor-->
  <!-- SENSOR 11 -->
  <!-- xacro:us_sensor name="us_11" parent="base_link">
    <origin xyz="0.100 0 0.300" rpy="0 3.14 3.14" />
  </xacro:us_sensor-->
  <!-- SENSOR 12 -->
  <!-- xacro:us_sensor name="us_12" parent="base_link">
    <origin xyz="0.190 0 0.300" rpy="0 3.14 3.14" />
  </xacro:us_sensor-->
  <!-- SENSOR 13 -->
  <!-- xacro:us_sensor name="us_13" parent="base_link">
    <origin xyz="0.200 0 0.300" rpy="0 3.14 3.14" />
  </xacro:us_sensor-->
  <!-- SENSOR 14 -->
  <!-- xacro:us_sensor name="us_14" parent="base_link">
    <origin xyz="0.210 0 0.300" rpy="0 3.14 3.14" />
  </xacro:us_sensor-->
  <!-- SENSOR 15 -->
  <!-- xacro:us_sensor name="us_15" parent="base_link">
    <origin xyz="0.220 0 0.300" rpy="0 3.14 3.14" />
  </xacro:us_sensor-->
  <!-- SENSOR 16 -->
  <!-- xacro:us_sensor name="us_16" parent="base_link">
    <origin xyz="0.230 0 0.300" rpy="0 3.14 3.14" />
  </xacro:us_sensor-->
  <!--Camera  -->
  <!-- <xacro:camera name="camera" parent="base_link">
    <origin xyz="0 0 0.38" rpy="0 0 0" />
  </xacro:camera> -->
  <joint name="cabinet_joint" type="fixed">
    <origin rpy="0 0 0" xyz="0.072 0 0.386"/>
    <joint_properties damping="1" friction="1"/>
    <parent link="base_link"/>
    <child link="cabinet_link"/>
  </joint>
  <link name="cabinet_link">
    <inertial>
      <mass value="2"/>
      <origin rpy="0 0 0" xyz="0 0 0"/>
      <inertia ixx="0.457072" ixy="0.0" ixz="0.0" iyy="0.23616" iyz="0.0" izz="0.686"/>
    </inertial>
    <visual>
      <origin rpy="0 0 -1.5708" xyz="0 0 0"/>
      <geometry>
        <mesh filename="package://neo_mpo_500-2/robot_model/meshes/MPO_500/cabin.dae" scale="0.001 0.001 0.001"/>
      </geometry>
    </visual>
    <collision>
      <origin rpy="0 0 0" xyz="0. 0. 0"/>
      <geometry>
        <mesh filename="package://neo_mpo_500-2/robot_model/meshes/MPO_500/cabin.dae" scale="0.001 0.001 0.001"/>
      </geometry>
    </collision>
  </link>
  <joint name="cabinet_u10_joint" type="fixed">
    <parent link="cabinet_link"/>
    <child link="ur10_base_link"/>
    <origin rpy="0.0 0.0 0.0" xyz="0.133 0.0 0.416"/>
  </joint>
  <link name="ur10_base_link">
    <visual>
      <geometry>
        <mesh filename="package://neo_mpo_500-2/robot_model/meshes/ur10/visual/base.dae"/>
      </geometry>
    </visual>
    <collision>
      <geometry>
        <mesh filename="package://neo_mpo_500-2/robot_model/meshes/ur10/visual/base.dae"/>
      </geometry>
    </collision>
    <inertial>
      <mass value="2.0"/>
      <origin rpy="0 0 0" xyz="0.0 0.0 0.0"/>
      <inertia ixx="0.0030531654454" ixy="0.0" ixz="0.0" iyy="0.0030531654454" iyz="0.0" izz="0.005625"/>
    </inertial>
  </link>
  <joint name="shoulder_pan_joint" type="revolute">
    <parent link="ur10_base_link"/>
    <child link="shoulder_link"/>
    <origin rpy="0.0 0.0 0.0" xyz="0.0 0.0 0.1273"/>
    <axis xyz="0 0 1"/>
    <limit effort="330.0" lower="-3.141592653589793" upper="3.141592653589793" velocity="2.16"/>
    <dynamics damping="0.5" friction="10.0"/>
  </joint>
  <link name="shoulder_link">
    <visual>
      <geometry>
        <mesh filename="package://neo_mpo_500-2/robot_model/meshes/ur10/visual/shoulder.dae"/>
      </geometry>
    </visual>
    <collision>
      <geometry>
        <mesh filename="package://neo_mpo_500-2/robot_model/meshes/ur10/visual/shoulder.dae"/>
      </geometry>
    </collision>
    <inertial>
      <mass value="7.778"/>
      <origin rpy="0 0 0" xyz="0.0 0.0 0.0"/>
      <inertia ixx="0.03147431257693659" ixy="0.0" ixz="0.0" iyy="0.03147431257693659" iyz="0.0" izz="0.021875624999999996"/>
    </inertial>
  </link>
  <joint name="shoulder_lift_joint" type="revolute">
    <parent link="shoulder_link"/>
    <child link="upper_arm_link"/>
    <origin rpy="0.0 -1.25 0.0" xyz="0.0 0.220941 0.0"/>
    <axis xyz="0 1 0"/>
    <limit effort="330.0" lower="-3.141592653589793" upper="3.141592653589793" velocity="2.16"/>
    <dynamics damping="0.5" friction="10.0"/>
  </joint>
  <link name="upper_arm_link">
    <visual>
      <geometry>
        <mesh filename="package://neo_mpo_500-2/robot_model/meshes/ur10/visual/upperarm.dae"/>
      </geometry>
    </visual>
    <collision>
      <geometry>
        <mesh filename="package://neo_mpo_500-2/robot_model/meshes/ur10/visual/upperarm.dae"/>
      </geometry>
    </collision>
    <inertial>
      <mass value="12.93"/>
      <origin rpy="0 0 0" xyz="0.0 0.0 0.306"/>
      <inertia ixx="0.42175380379841093" ixy="0.0" ixz="0.0" iyy="0.42175380379841093" iyz="0.0" izz="0.03636562499999999"/>
    </inertial>
  </link>
  <joint name="elbow_joint" type="revolute">
    <parent link="upper_arm_link"/>
    <child link="forearm_link"/>
    <origin rpy="0.0 -1.95 0.0" xyz="0.0 -0.1719 0.612"/>
    <axis xyz="0 1 0"/>
    <limit effort="150.0" lower="-3.141592653589793" upper="3.141592653589793" velocity="3.15"/>
    <dynamics damping="0.5" friction="10.0"/>
  </joint>
  <link name="forearm_link">
    <visual>
      <geometry>
        <mesh filename="package://neo_mpo_500-2/robot_model/meshes/ur10/visual/forearm.dae"/>
      </geometry>
    </visual>
    <collision>
      <geometry>
        <mesh filename="package://neo_mpo_500-2/robot_model/meshes/ur10/visual/forearm.dae"/>
      </geometry>
    </collision>
    <inertial>
      <mass value="3.87"/>
      <origin rpy="0 0 0" xyz="0.0 0.0 0.28615"/>
      <inertia ixx="0.11106969409710458" ixy="0.0" ixz="0.0" iyy="0.11106969409710458" iyz="0.0" izz="0.010884375"/>
    </inertial>
  </link>
  <joint name="wrist_1_joint" type="revolute">
    <parent link="forearm_link"/>
    <child link="wrist_1_link"/>
    <origin rpy="0.0 1.5707963267948966 0.0" xyz="0.0 0.0 0.5723"/>
    <axis xyz="0 1 0"/>
    <limit effort="54.0" lower="-3.141592653589793" upper="3.141592653589793" velocity="3.2"/>
    <dynamics damping="0.5" friction="10.0"/>
  </joint>
  <link name="wrist_1_link">
    <visual>
      <geometry>
        <mesh filename="package://neo_mpo_500-2/robot_model/meshes/ur10/visual/wrist1.dae"/>
      </geometry>
    </visual>
    <collision>
      <geometry>
        <mesh filename="package://neo_mpo_500-2/robot_model/meshes/ur10/visual/wrist1.dae"/>
      </geometry>
    </collision>
    <inertial>
      <mass value="1.96"/>
      <origin rpy="0 0 0" xyz="0.0 0.0 0.0"/>
      <inertia ixx="0.005108247956699999" ixy="0.0" ixz="0.0" iyy="0.005108247956699999" iyz="0.0" izz="0.005512499999999999"/>
    </inertial>
  </link>
  <joint name="wrist_2_joint" type="revolute">
    <parent link="wrist_1_link"/>
    <child link="wrist_2_link"/>
    <origin rpy="0.0 0.0 0.0" xyz="0.0 0.1149 0.0"/>
    <axis xyz="0 0 1"/>
    <limit effort="54.0" lower="-3.141592653589793" upper="3.141592653589793" velocity="3.2"/>
    <dynamics damping="0.5" friction="10.0"/>
  </joint>
  <link name="wrist_2_link">
    <visual>
      <geometry>
        <mesh filename="package://neo_mpo_500-2/robot_model/meshes/ur10/visual/wrist2.dae"/>
      </geometry>
    </visual>
    <collision>
      <geometry>
        <mesh filename="package://neo_mpo_500-2/robot_model/meshes/ur10/visual/wrist2.dae"/>
      </geometry>
    </collision>
    <inertial>
      <mass value="1.96"/>
      <origin rpy="0 0 0" xyz="0.0 0.0 0.0"/>
      <inertia ixx="0.005108247956699999" ixy="0.0" ixz="0.0" iyy="0.005108247956699999" iyz="0.0" izz="0.005512499999999999"/>
    </inertial>
  </link>
  <joint name="wrist_3_joint" type="revolute">
    <parent link="wrist_2_link"/>
    <child link="wrist_3_link"/>
    <origin rpy="0.0 0.0 0.0" xyz="0.0 0.0 0.1157"/>
    <axis xyz="0 1 0"/>
    <limit effort="54.0" lower="-3.141592653589793" upper="3.141592653589793" velocity="3.2"/>
    <dynamics damping="0.5" friction="10.0"/>
  </joint>
  <link name="wrist_3_link">
    <visual>
      <geometry>
        <mesh filename="package://neo_mpo_500-2/robot_model/meshes/ur10/visual/wrist3.dae"/>
      </geometry>
    </visual>
    <collision>
      <geometry>
        <mesh filename="package://neo_mpo_500-2/robot_model/meshes/ur10/visual/wrist3.dae"/>
      </geometry>
    </collision>
    <inertial>
      <mass value="0.202"/>
      <origin rpy="0 0 0" xyz="0.0 0.0 0.0"/>
      <inertia ixx="0.000526462289415" ixy="0.0" ixz="0.0" iyy="0.000526462289415" iyz="0.0" izz="0.0005681249999999999"/>
    </inertial>
  </link>
  <joint name="ee_fixed_joint" type="fixed">
    <parent link="wrist_3_link"/>
    <child link="ee_link"/>
    <origin rpy="0.0 0.0 1.5707963267948966" xyz="0.0 0.0922 0.0"/>
  </joint>
  <link name="ee_link">
    <collision>
      <geometry>
        <box size="0.01 0.01 0.01"/>
      </geometry>
      <origin rpy="0 0 0" xyz="-0.01 0 0"/>
    </collision>
  </link>
</robot>
